/**
Ejercicio 1: Divisi√≥n por cero
void dividir(int a, int b) {
  // TODO: Si b es 0, lanza una excepci√≥n con throw
  print(a / b);
}

void main() {
  try {
    dividir(10, 0);
  } 
  // TODO: Atrapa la excepci√≥n y muestra "Error: divisi√≥n por cero"
}
 */

void dividir(int a, int b) {
  if (b == 0) {
    throw Exception("No se puede dividir entre cero");
  }
  print(a / b);
}

void main() {
  try {
    dividir(10, 0);
  } catch (e) {
    print("Error atrapado: $e");
  }
}

/**
Ejercicio 2: √çndice fuera de rango
void main() {
  var lista = [1, 2, 3];

  try {
    print(lista[5]); // ‚ùå Esto da error
  } 
  // TODO: Usa on RangeError para capturar este error en espec√≠fico
}
 */

void main() {
  var lista = [1, 2, 3];

  try {
    print(lista[5]);
  } on RangeError catch (e) {
    print("Error atrapado: $e");
  } catch (e) {
    print("Otro error atrapado: $e");
  }
}

/**
Ejercicio 3: Formato inv√°lido
void main() {
  try {
    var numero = int.parse("abc"); // ‚ùå Esto da FormatException
    print(numero);
  } 
  // TODO: Usa on FormatException y muestra un mensaje claro
}
 */

void main() {
  try {
    var numero = int.parse("abc");
    print(numero);
  } on FormatException catch (e) {
    print("Error de formato atrapado: $e");
  } catch (e) {
    print("Otro error atrapado: $e");
  }
}

/**
Ejercicio 4: Uso de finally
void abrirArchivo() {
  print("üìÇ Archivo abierto");
  throw Exception("Error al leer archivo");
}

void main() {
  try {
    abrirArchivo();
  } 
  // TODO: Captura el error
  // TODO: A√±ade un bloque finally que muestre "üìï Archivo cerrado"
}
 */

void abrirArchivo() {
  print("üìÇ Archivo abierto");
  throw Exception("Error al leer archivo");
}

void main() {
  try {
    abrirArchivo();
  } catch (e) {
    print("Error atrapado: $e");
  } finally {
    print("üìï Archivo cerrado");
  }
}

/**
Ejercicio 5: Excepci√≥n personalizada
// TODO: Crea una clase DivisionPorCeroException que implemente Exception
//       y sobrescriba toString() para mostrar "üö´ Divisi√≥n prohibida"

void dividir(int a, int b) {
  // TODO: Lanza tu excepci√≥n personalizada si b == 0
  print(a / b);
}

void main() {
  try {
    dividir(8, 0);
  } 
  // TODO: Atrapa tu excepci√≥n personalizada y mu√©strala
}
 */

class DivisionPorCeroException implements Exception {
  @override
  String toString() => "üö´ Divisi√≥n prohibida";
}

void dividir(int a, int b) {
  if (b == 0) {
    throw DivisionPorCeroException();
  }
  print(a / b);
}

void main() {
  try {
    dividir(8, 0);
  } on DivisionPorCeroException catch (e) {
    print("Error atrapado: $e");
  } catch (e) {
    print("Otro error atrapado: $e");
  }
}

/**
Ejercicio 6: Async y manejo de errores
Future<void> cargarDatos() async {
  await Future.delayed(Duration(seconds: 1));
  // TODO: Lanza una excepci√≥n aqu√≠ simulando un fallo de conexi√≥n
}

void main() async {
  try {
    await cargarDatos();
  } 
  // TODO: Atrapa el error y muestra "Error: no se pudieron cargar los datos"
}
 */

Future<void> cargarDatos() async {
  await Future.delayed(Duration(seconds: 1));
  throw Exception("Fallo de conexi√≥n");
}

void main() async {
  try {
    await cargarDatos();
  } catch (e) {
    print("Error: no se pudieron cargar los datos - $e");
  }
}
